<?xml version="1.0" ?>
<!-- =================================================================================== -->
<!-- |    This document was autogenerated by xacro from rviz_car.urdf                  | -->
<!-- |    EDITING THIS FILE BY HAND IS NOT RECOMMENDED                                 | -->
<!-- =================================================================================== -->
<robot name="BMW">
  <material name="black">
    <color rgba="0 0 0 1"/>
  </material>
  <material name="white">
    <color rgba="1 1 1 1"/>
  </material>
  <link name="base_link">
    <visual>
      <origin xyz="0 0.9055 -0.1"/>
      <geometry>
        <mesh filename="package://rviz_car/model/car_support.stl"/>
      </geometry>
    </visual>
  </link>
  <link name="rear_left_wheel">
    <visual>
      <geometry>
        <cylinder length="0.3" radius="0.3"/>
      </geometry>
      <origin rpy="1.5707963267948966 0 0" xyz="0 0 0"/>
      <material name="black"/>
    </visual>
  </link>
  <joint name="body_to_rear_left_wheel" type="continuous">
    <axis xyz="0 1 0"/>
    <parent link="base_link"/>
    <child link="rear_left_wheel"/>
    <origin xyz="3.55 -0.7555 0"/>
    <limit effort="1000.0" velocity="0.5"/>
  </joint>
  <link name="rear_right_wheel">
    <visual>
      <geometry>
        <cylinder length="0.3" radius="0.3"/>
      </geometry>
      <origin rpy="1.5707963267948966 0 0" xyz="0 0 0"/>
      <material name="black"/>
    </visual>
  </link>
  <joint name="body_to_rear_right_wheel" type="continuous">
    <axis xyz="0 1 0"/>
    <parent link="base_link"/>
    <child link="rear_right_wheel"/>
    <origin xyz="3.55 0.7555 0"/>
    <limit effort="1000.0" velocity="0.5"/>
  </joint>
  <link name="front_left_wheel">
    <visual>
      <geometry>
        <cylinder length="0.3" radius="0.3"/>
      </geometry>
      <origin rpy="1.5707963267948966 0 0" xyz="0 0 0"/>
      <material name="black"/>
    </visual>
  </link>
  <link name="front_left_wheel_pivot">
    <visual>
      <geometry>
        <sphere radius="1e-3"/>
      </geometry>
    </visual>
  </link>
  <joint name="body_to_front_left_pivot" type="revolute">
    <limit effort="1000.0" lower="-0.7853981633974483" upper="0.7853981633974483" velocity="0.5"/>
    <axis xyz="0 0 1"/>
    <parent link="base_link"/>
    <child link="front_left_wheel_pivot"/>
    <origin xyz="0.65 -0.7555 0"/>
  </joint>
  <joint name="pivot_to_front_left_wheel" type="continuous">
    <axis xyz="0 1 0"/>
    <parent link="front_left_wheel_pivot"/>
    <child link="front_left_wheel"/>
    <origin xyz="0 0 0"/>
    <limit effort="1000.0" velocity="20.5"/>
  </joint>
  <link name="front_right_wheel">
    <visual>
      <geometry>
        <cylinder length="0.3" radius="0.3"/>
      </geometry>
      <origin rpy="1.5707963267948966 0 0" xyz="0 0 0"/>
      <material name="black"/>
    </visual>
  </link>
  <link name="front_right_wheel_pivot">
    <visual>
      <geometry>
        <sphere radius="1e-3"/>
      </geometry>
    </visual>
  </link>
  <joint name="body_to_front_right_pivot" type="revolute">
    <limit effort="1000.0" lower="-0.7853981633974483" upper="0.7853981633974483" velocity="0.5"/>
    <axis xyz="0 0 1"/>
    <parent link="base_link"/>
    <child link="front_right_wheel_pivot"/>
    <origin xyz="0.65 0.7555 0"/>
    <mimic joint="body_to_front_left_pivot"/>
  </joint>
  <joint name="pivot_to_front_right_wheel" type="continuous">
    <axis xyz="0 1 0"/>
    <parent link="front_right_wheel_pivot"/>
    <child link="front_right_wheel"/>
    <origin xyz="0 0 0"/>
    <limit effort="1000.0" velocity="20.5"/>
  </joint>
  <link name="trimble_front_sensor">
    <geometry>
      <box size="0.1 0.1 0.05"/>
    </geometry>
    <origin rpy="0 0 0" xyz="0 0 0"/>
    <material name="white"/>
  </link>
  <joint name="trimble_front_sensor_joint" type="fixed">
    <parent name="base_link"/>
    <child name="trimble_front_sensor"/>
    <origin rpy="0 0 0" xyz="1.9 0.5 1.5"/>
  </joint>
</robot>
