<?xml version="1.0"?>
<robot name="BMW" xmlns:xacro="http://ros.org/wiki/xacro">

    <xacro:property name="c_len" value="4.633"/>
    <xacro:property name="c_width" value="1.811"/>
    <xacro:property name="c_height" value="1.429"/>
    <xacro:property name="w_diam" value="0.6"/>
    <xacro:property name="w_width" value="0.3"/>
    <xacro:property name="wheel_mass" value="10"/>

    <material name="black">
        <color rgba="0 0 0 1"/>
    </material>
    
    <link name="base_link">
        <visual>
            <origin xyz="0 ${c_width/2} 0"/>
            <geometry>
                <mesh filename="package://rviz_car/model/car.dae"/>
            </geometry>
        </visual>
        <collision>
            <origin xyz="0 ${c_width/2} 0"/>
            <geometry>
                <mesh filename="package://rviz_car/model/car.dae"/>
            </geometry>
        </collision>
        <inertial>
            <mass value="500.0" />
            <inertia ixx="1.0" ixy="0.0" ixz="0.0" iyy="1.0" iyz="0.0" izz="1.0" />
            <origin xyz="${c_len/2} 0 ${c_height/2}"/>
        </inertial>
    </link>

    <link name="wheel_pivot">
        <visual>
            <geometry>
                <sphere radius="1e-1"/>
            </geometry>
        </visual>
        <collision>
            <geometry>
                <sphere radius="1e-5"/>
            </geometry>
        </collision>
        <inertial>
            <mass value="1" />
            <inertia ixx="1" ixy="0.0" ixz="0.0" iyy="1" iyz="0.0" izz="1" />
        </inertial>
    </link>

    <joint name="body_to_pivot" type="revolute">
        <limit effort="1000.0" lower="${-pi/4}" upper="${pi/4}" velocity="0.5"/>
        <axis xyz="0 0 1"/>
        <parent link="base_link"/>
        <child link="wheel_pivot"/>
        <origin xyz="0.65 0 0"/>
    </joint>

    <!-- front is 0/1; right is -1/1-->
    <xacro:macro name="wheel" params="front right prefix mimic:=''">
        <link name="${prefix}_wheel">
            <visual>
                <geometry>
                    <cylinder length="${w_width}" radius="${w_diam/2}"/>
                </geometry>
                <origin rpy="${pi/2} 0 0" xyz="0 0 0"/>
                <material name="black"/>
            </visual>
            <collision>
                <geometry>
                    <cylinder length="${w_width}" radius="${w_diam/2}"/>
                </geometry>
                <origin rpy="${pi/2} 0 0" xyz="0 0 0"/>
            </collision>
            <inertial>
                <mass value="${wheel_mass}"/>
                <inertia ixx="${(1/12)*wheel_mass*(3*0.25*w_diam*w_diam + w_width*w_width)}" ixy="0" ixz="0" 
                         iyy="${0.125*wheel_mass*w_diam*w_diam}" iyz="0" izz="${(1/12)*wheel_mass*(3*0.25*w_diam*w_diam + w_width*w_width)}"/>
            </inertial>
        </link>

        <xacro:if value="${front==1}">
            <joint name="pivot_to_${prefix}_wheel" type="continuous">
                <limit effort="1000.0" lower="0" upper="${2*pi}" velocity="1.5"/>
                <axis xyz="0 1 0"/>
                <parent link="wheel_pivot"/>
                <child link="${prefix}_wheel"/>
                <origin xyz="0 ${right*(c_width/2 - w_width/2)} 0"/>
            </joint>
        </xacro:if>

        <xacro:if value="${front==0}">
            <joint name="body_to_${prefix}_wheel" type="continuous">
                <axis xyz="0 1 0"/>
                <parent link="base_link"/>
                <child link="${prefix}_wheel"/>
                <origin xyz="3.55 ${right*(c_width/2 - w_width/2)} 0"/>
            </joint>
        </xacro:if>

    </xacro:macro>

    <xacro:wheel front="0" right="-1" prefix="rear_left"/>
    <xacro:wheel front="0" right="1" prefix="rear_right"/>
    <xacro:wheel front="1" right="-1" prefix="front_left"/>
    <xacro:wheel front="1" right="1" prefix="front_right" mimic="front_left"/>

    <gazebo>
        <plugin name="gazebo_ros_control" filename="libgazebo_ros_control.so">
        <robotNamespace>/</robotNamespace>
        </plugin>
    </gazebo>
</robot>