<?xml version="1.0"?>
<!-- Ajouter base_foot_print from bqse link-->
<robot name="BMW" xmlns:xacro="http://ros.org/wiki/xacro">

    <xacro:property name="c_len" value="4.633"/>
    <xacro:property name="c_width" value="1.811"/>
    <xacro:property name="c_height" value="1.429"/>
    <xacro:property name="w_diam" value="0.6"/>
    <xacro:property name="w_width" value="0.3"/>

    <material name="black">
        <color rgba="0 0 0 1"/>
    </material>

    <material name="white">
        <color rgba="1 1 1 1"/>
    </material>
    
    <material name="orange">
        <color rgba="1 0.65 0 1"/>
    </material>

    <material name="blue">
        <color rgba="0 0.05 1 1"/>
    </material>

    <link name="base_footprint">
        <visual>
            <origin xyz="0 -${c_width/2} 0.20" rpy="0 0 ${pi}"/>
            <geometry>
                <mesh filename="package://rviz_car/model/car_support.stl"/>
            </geometry>
            <material name="white"/>
        </visual>
    </link>
    <joint name="link_to_footprint" type="fixed">
        <parent link="base_link"/>
        <child link="base_footprint"/>
        <origin xyz="0 0 0" rpy="0 0 ${pi/2}"/>
    </joint>
    <link name="base_link">
    </link>

    <link name="odom_base"/>
    <joint name="odom_to_foot" type="fixed">
        <parent link="base_footprint"/>
        <child link="odom_base"/>
        <origin xyz="${-c_len/2} 0 0" rpy="0 0 0"/>
    </joint>

    <xacro:macro name="sensor" params="prefix parent:='base_footprint' color:=white *origin *joint_origin *geom">
        <link name="${prefix}_sensor">
            <visual>
                <xacro:insert_block name="geom"/>
                <xacro:insert_block name="origin"/>
                <material name="${color}"/>
            </visual>
        </link>
        <joint name="${prefix}_sensor_joint" type="fixed">
            <parent link="${parent}"/>
            <child link="${prefix}_sensor"/>
            <xacro:insert_block name="joint_origin"/>
        </joint>
    </xacro:macro>

    <xacro:macro name="simple_box" params="dims">
        <geometry>
            <box size="${dims}"/>
        </geometry>
    </xacro:macro>
    <xacro:macro name="simple_cylinder" params="radius length">
        <geometry>
            <cylinder radius="${radius}" length="${length}"/>
        </geometry>
    </xacro:macro>

    <!-- front is 0/1; right is -1/1-->
    <xacro:macro name="wheel" params="front right prefix mimic:=''">
        <link name="${prefix}_wheel">
            <visual>
                <geometry>
                    <cylinder length="${w_width}" radius="${w_diam/2}"/>
                </geometry>
                <origin rpy="${pi/2} 0 0" xyz="0 0 0"/>
                <material name="black"/>
            </visual>
        </link>

        <xacro:if value="${front==1}">
            <link name="${prefix}_wheel_pivot">
                <visual>
                    <geometry>
                        <sphere radius="1e-3"/>
                    </geometry>
                </visual>
            </link>

            <joint name="body_to_${prefix}_pivot" type="revolute">
                <limit effort="1000.0" lower="${-pi/4}" upper="${pi/4}" velocity="0.5"/>
                <axis xyz="0 0 1"/>
                <parent link="base_footprint"/>
                <child link="${prefix}_wheel_pivot"/>
                <origin xyz="-0.65 ${-1*right*(c_width/2 - w_width/2)} ${w_diam/2}"/>
                <xacro:if value="${mimic != ''}">
                    <mimic joint="body_to_${mimic}_pivot"/>
                </xacro:if>
            </joint>

            <joint name="pivot_to_${prefix}_wheel" type="continuous">
                <axis xyz="0 1 0"/>
                <parent link="${prefix}_wheel_pivot"/>
                <child link="${prefix}_wheel"/>
                <origin xyz="0 0 0"/>
                <limit effort="1000.0" velocity="20.5"/>
            </joint>
            
        </xacro:if>

        <xacro:if value="${front==0}">
            <joint name="body_to_${prefix}_wheel" type="continuous">
                <axis xyz="0 1 0"/>
                <parent link="base_footprint"/>
                <child link="${prefix}_wheel"/>
                <origin xyz="-3.55 ${-1*right*(c_width/2 - w_width/2)} ${w_diam/2}"/>
                <limit effort="1000.0" velocity="0.5"/>
            </joint>
        </xacro:if>

    </xacro:macro>

    <xacro:wheel front="0" right="-1" prefix="rear_left"/>
    <xacro:wheel front="0" right="1" prefix="rear_right"/>
    <xacro:wheel front="1" right="-1" prefix="front_left"/>
    <xacro:wheel front="1" right="1" prefix="front_right" mimic="front_left"/>

    <xacro:sensor prefix="trimble_front" color="white">
        <origin xyz="0.05 0.05 0.025" rpy="0 0 0"/>
        <origin xyz="-1.94 -0.5 1.779" rpy="0 0 0"/>
        <xacro:simple_box dims="0.1 0.1 0.05"/>
    </xacro:sensor>
    
    <xacro:sensor prefix="mobileye" color="white">
        <origin xyz="0.05 0.05 0.025" rpy="0 0 0"/>
        <origin xyz="-2.6 0.0 0.0" rpy="0 0 0"/>
        <xacro:simple_box dims="0.1 0.1 0.05"/>
    </xacro:sensor>

    <xacro:sensor prefix="IMU" color="orange">
        <origin xyz="0 0 0" rpy="0 0 0"/>
        <origin xyz="-4.033 -0.1 0.7" rpy="0 0 0"/>
        <xacro:simple_cylinder radius="0.05" length="0.02"/>
    </xacro:sensor>
    <xacro:sensor prefix="Ublox" color="white">
        <origin xyz="0 0 0" rpy="0 0 0"/>
        <origin xyz="-3.33 0.5245 1.6" rpy="0 0 0"/>
        <xacro:simple_cylinder radius="0.07" length="0.1"/>
    </xacro:sensor>

    <xacro:sensor prefix="ADMA" color="blue" parent="trimble_front_sensor">
        <origin xyz="0 0 0" rpy="0 0 0"/>
        <origin xyz="-1.1 0.5 0.0" rpy="0 0 0"/>
        <xacro:simple_box dims="0.2 0.15 0.05"/>
    </xacro:sensor>
</robot>
